Creating test database for alias 'default' ('file:memorydb_default?mode=memory&cache=shared')...
Operations to perform:
  Synchronize unmigrated apps: messages, rest_framework, staticfiles
  Apply all migrations: admin, auth, authtoken, contenttypes, kanvas_app, sessions
Synchronizing apps without migrations:
  Creating tables...
    Running deferred SQL...
Running migrations:
  Applying contenttypes.0001_initial... OK
  Applying auth.0001_initial... OK
  Applying admin.0001_initial... OK
  Applying admin.0002_logentry_remove_auto_add... OK
  Applying admin.0003_logentry_add_action_flag_choices... OK
  Applying contenttypes.0002_remove_content_type_name... OK
  Applying auth.0002_alter_permission_name_max_length... OK
  Applying auth.0003_alter_user_email_max_length... OK
  Applying auth.0004_alter_user_username_opts... OK
  Applying auth.0005_alter_user_last_login_null... OK
  Applying auth.0006_require_contenttypes_0002... OK
  Applying auth.0007_alter_validators_add_error_messages... OK
  Applying auth.0008_alter_user_username_max_length... OK
  Applying auth.0009_alter_user_last_name_max_length... OK
  Applying auth.0010_alter_group_name_max_length... OK
  Applying auth.0011_update_proxy_permissions... OK
  Applying auth.0012_alter_user_first_name_max_length... OK
  Applying authtoken.0001_initial... OK
  Applying authtoken.0002_auto_20160226_1747... OK
  Applying authtoken.0003_tokenproxy... OK
  Applying kanvas_app.0001_initial... OK
  Applying kanvas_app.0002_activities_submissions... OK
  Applying kanvas_app.0003_alter_submissions_grade... OK
  Applying kanvas_app.0004_alter_submissions_grade... OK
  Applying kanvas_app.0005_alter_submissions_grade... OK
  Applying kanvas_app.0006_alter_submissions_user_id... OK
  Applying kanvas_app.0007_auto_20210809_1821... OK
  Applying sessions.0001_initial... OK
System check identified no issues (0 silenced).
test_create_and_login_for_facilitator_account (test_api.TestAccountView) ... FAIL
test_create_and_login_for_instructor_account (test_api.TestAccountView) ... FAIL
test_create_and_login_for_student_account (test_api.TestAccountView) ... FAIL
test_create_two_equals_users (test_api.TestAccountView) ... FAIL
test_wrong_credentials_do_not_login (test_api.TestAccountView) ... ok
test_facilitator_or_instructor_can_create_an_activity (test_api.TestActivityView) ... ok
test_facilitator_or_instructor_can_edit_a_submission_grade (test_api.TestActivityView) ... ok
test_facilitator_or_instructor_can_list_activities (test_api.TestActivityView) ... ok
test_facilitator_or_instructor_can_view_all_submissions (test_api.TestActivityView) ... ok
test_facilitator_or_instructor_cannot_submity_an_activity (test_api.TestActivityView) ... ok
test_if_it_is_not_possible_to_create_activities_with_the_same_title (test_api.TestActivityView) ... ERROR
test_student_can_submit_an_activity (test_api.TestActivityView) ... FAIL
test_student_can_view_only_your_submissions (test_api.TestActivityView) ... FAIL
test_student_cannot_edit_a_submission_grade (test_api.TestActivityView) ... ok
test_student_cannot_list_activities (test_api.TestActivityView) ... ok
test_students_cannot_create_activities (test_api.TestActivityView) ... ok
test_anonymous_can_filter_courses (test_api.TestCourseView) ... FAIL
test_anonymous_can_list_courses (test_api.TestCourseView) ... ok
test_anonymous_cannot_filter_invalid_course (test_api.TestCourseView) ... ok
test_create_course_with_invalid_token (test_api.TestCourseView) ... ok
test_create_two_courses_with_the_same_name_generate_the_same_ids (test_api.TestCourseView) ... ok
test_enroll_students_with_invalid_id (test_api.TestCourseView) ... FAIL
test_enrolls_students_with_invalid_course_id (test_api.TestCourseView) ... ok
test_facilitator_or_student_cannot_create_course (test_api.TestCourseView) ... ok
test_instructor_can_create_course (test_api.TestCourseView) ... ok
test_instructor_can_delete_courses (test_api.TestCourseView) ... ok
test_instructor_can_register_students_on_course (test_api.TestCourseView) ... ok
test_only_students_can_be_enrolled_in_the_course (test_api.TestCourseView) ... ok
test_student_or_facilitator_cannot_delete_courses (test_api.TestCourseView) ... ok
test_whether_a_list_is_entered_to_enroll_students_in_the_course (test_api.TestCourseView) ... ok

======================================================================
ERROR: test_if_it_is_not_possible_to_create_activities_with_the_same_title (test_api.TestActivityView)
----------------------------------------------------------------------
Traceback (most recent call last):
  File "/home/nathan/Área de Trabalho/python/Q4/Kanvas/venv/lib/python3.9/site-packages/django/db/models/query.py", line 581, in get_or_create
    return self.get(**kwargs), False
  File "/home/nathan/Área de Trabalho/python/Q4/Kanvas/venv/lib/python3.9/site-packages/django/db/models/query.py", line 435, in get
    raise self.model.DoesNotExist(
kanvas_app.models.Activities.DoesNotExist: Activities matching query does not exist.

During handling of the above exception, another exception occurred:

Traceback (most recent call last):
  File "/home/nathan/Área de Trabalho/python/Q4/Kanvas/venv/lib/python3.9/site-packages/django/db/backends/utils.py", line 84, in _execute
    return self.cursor.execute(sql, params)
  File "/home/nathan/Área de Trabalho/python/Q4/Kanvas/venv/lib/python3.9/site-packages/django/db/backends/sqlite3/base.py", line 423, in execute
    return Database.Cursor.execute(self, query, params)
sqlite3.IntegrityError: UNIQUE constraint failed: kanvas_app_activities.title

The above exception was the direct cause of the following exception:

Traceback (most recent call last):
  File "/home/nathan/Área de Trabalho/python/Q4/Kanvas/test_api.py", line 768, in test_if_it_is_not_possible_to_create_activities_with_the_same_title
    activity2 = self.client.post(
  File "/home/nathan/Área de Trabalho/python/Q4/Kanvas/venv/lib/python3.9/site-packages/rest_framework/test.py", line 295, in post
    response = super().post(
  File "/home/nathan/Área de Trabalho/python/Q4/Kanvas/venv/lib/python3.9/site-packages/rest_framework/test.py", line 209, in post
    return self.generic('POST', path, data, content_type, **extra)
  File "/home/nathan/Área de Trabalho/python/Q4/Kanvas/venv/lib/python3.9/site-packages/rest_framework/test.py", line 233, in generic
    return super().generic(
  File "/home/nathan/Área de Trabalho/python/Q4/Kanvas/venv/lib/python3.9/site-packages/django/test/client.py", line 473, in generic
    return self.request(**r)
  File "/home/nathan/Área de Trabalho/python/Q4/Kanvas/venv/lib/python3.9/site-packages/rest_framework/test.py", line 285, in request
    return super().request(**kwargs)
  File "/home/nathan/Área de Trabalho/python/Q4/Kanvas/venv/lib/python3.9/site-packages/rest_framework/test.py", line 237, in request
    request = super().request(**kwargs)
  File "/home/nathan/Área de Trabalho/python/Q4/Kanvas/venv/lib/python3.9/site-packages/django/test/client.py", line 719, in request
    self.check_exception(response)
  File "/home/nathan/Área de Trabalho/python/Q4/Kanvas/venv/lib/python3.9/site-packages/django/test/client.py", line 580, in check_exception
    raise exc_value
  File "/home/nathan/Área de Trabalho/python/Q4/Kanvas/venv/lib/python3.9/site-packages/django/core/handlers/exception.py", line 47, in inner
    response = get_response(request)
  File "/home/nathan/Área de Trabalho/python/Q4/Kanvas/venv/lib/python3.9/site-packages/django/core/handlers/base.py", line 181, in _get_response
    response = wrapped_callback(request, *callback_args, **callback_kwargs)
  File "/home/nathan/Área de Trabalho/python/Q4/Kanvas/venv/lib/python3.9/site-packages/django/views/decorators/csrf.py", line 54, in wrapped_view
    return view_func(*args, **kwargs)
  File "/home/nathan/Área de Trabalho/python/Q4/Kanvas/venv/lib/python3.9/site-packages/django/views/generic/base.py", line 70, in view
    return self.dispatch(request, *args, **kwargs)
  File "/home/nathan/Área de Trabalho/python/Q4/Kanvas/venv/lib/python3.9/site-packages/rest_framework/views.py", line 509, in dispatch
    response = self.handle_exception(exc)
  File "/home/nathan/Área de Trabalho/python/Q4/Kanvas/venv/lib/python3.9/site-packages/rest_framework/views.py", line 469, in handle_exception
    self.raise_uncaught_exception(exc)
  File "/home/nathan/Área de Trabalho/python/Q4/Kanvas/venv/lib/python3.9/site-packages/rest_framework/views.py", line 480, in raise_uncaught_exception
    raise exc
  File "/home/nathan/Área de Trabalho/python/Q4/Kanvas/venv/lib/python3.9/site-packages/rest_framework/views.py", line 506, in dispatch
    response = handler(request, *args, **kwargs)
  File "/home/nathan/Área de Trabalho/python/Q4/Kanvas/kanvas_app/views.py", line 135, in post
    activity = Activities.objects.get_or_create(**serializer.validated_data)[0]
  File "/home/nathan/Área de Trabalho/python/Q4/Kanvas/venv/lib/python3.9/site-packages/django/db/models/manager.py", line 85, in manager_method
    return getattr(self.get_queryset(), name)(*args, **kwargs)
  File "/home/nathan/Área de Trabalho/python/Q4/Kanvas/venv/lib/python3.9/site-packages/django/db/models/query.py", line 588, in get_or_create
    return self.create(**params), True
  File "/home/nathan/Área de Trabalho/python/Q4/Kanvas/venv/lib/python3.9/site-packages/django/db/models/query.py", line 453, in create
    obj.save(force_insert=True, using=self.db)
  File "/home/nathan/Área de Trabalho/python/Q4/Kanvas/venv/lib/python3.9/site-packages/django/db/models/base.py", line 726, in save
    self.save_base(using=using, force_insert=force_insert,
  File "/home/nathan/Área de Trabalho/python/Q4/Kanvas/venv/lib/python3.9/site-packages/django/db/models/base.py", line 763, in save_base
    updated = self._save_table(
  File "/home/nathan/Área de Trabalho/python/Q4/Kanvas/venv/lib/python3.9/site-packages/django/db/models/base.py", line 868, in _save_table
    results = self._do_insert(cls._base_manager, using, fields, returning_fields, raw)
  File "/home/nathan/Área de Trabalho/python/Q4/Kanvas/venv/lib/python3.9/site-packages/django/db/models/base.py", line 906, in _do_insert
    return manager._insert(
  File "/home/nathan/Área de Trabalho/python/Q4/Kanvas/venv/lib/python3.9/site-packages/django/db/models/manager.py", line 85, in manager_method
    return getattr(self.get_queryset(), name)(*args, **kwargs)
  File "/home/nathan/Área de Trabalho/python/Q4/Kanvas/venv/lib/python3.9/site-packages/django/db/models/query.py", line 1270, in _insert
    return query.get_compiler(using=using).execute_sql(returning_fields)
  File "/home/nathan/Área de Trabalho/python/Q4/Kanvas/venv/lib/python3.9/site-packages/django/db/models/sql/compiler.py", line 1416, in execute_sql
    cursor.execute(sql, params)
  File "/home/nathan/Área de Trabalho/python/Q4/Kanvas/venv/lib/python3.9/site-packages/django/db/backends/utils.py", line 66, in execute
    return self._execute_with_wrappers(sql, params, many=False, executor=self._execute)
  File "/home/nathan/Área de Trabalho/python/Q4/Kanvas/venv/lib/python3.9/site-packages/django/db/backends/utils.py", line 75, in _execute_with_wrappers
    return executor(sql, params, many, context)
  File "/home/nathan/Área de Trabalho/python/Q4/Kanvas/venv/lib/python3.9/site-packages/django/db/backends/utils.py", line 84, in _execute
    return self.cursor.execute(sql, params)
  File "/home/nathan/Área de Trabalho/python/Q4/Kanvas/venv/lib/python3.9/site-packages/django/db/utils.py", line 90, in __exit__
    raise dj_exc_value.with_traceback(traceback) from exc_value
  File "/home/nathan/Área de Trabalho/python/Q4/Kanvas/venv/lib/python3.9/site-packages/django/db/backends/utils.py", line 84, in _execute
    return self.cursor.execute(sql, params)
  File "/home/nathan/Área de Trabalho/python/Q4/Kanvas/venv/lib/python3.9/site-packages/django/db/backends/sqlite3/base.py", line 423, in execute
    return Database.Cursor.execute(self, query, params)
django.db.utils.IntegrityError: UNIQUE constraint failed: kanvas_app_activities.title

======================================================================
FAIL: test_create_and_login_for_facilitator_account (test_api.TestAccountView)
----------------------------------------------------------------------
Traceback (most recent call last):
  File "/home/nathan/Área de Trabalho/python/Q4/Kanvas/test_api.py", line 81, in test_create_and_login_for_facilitator_account
    self.assertEqual(facilitator_user.status_code, 201)
AssertionError: 200 != 201

======================================================================
FAIL: test_create_and_login_for_instructor_account (test_api.TestAccountView)
----------------------------------------------------------------------
Traceback (most recent call last):
  File "/home/nathan/Área de Trabalho/python/Q4/Kanvas/test_api.py", line 101, in test_create_and_login_for_instructor_account
    self.assertEqual(instructor_user.status_code, 201)
AssertionError: 200 != 201

======================================================================
FAIL: test_create_and_login_for_student_account (test_api.TestAccountView)
----------------------------------------------------------------------
Traceback (most recent call last):
  File "/home/nathan/Área de Trabalho/python/Q4/Kanvas/test_api.py", line 56, in test_create_and_login_for_student_account
    self.assertEqual(student_user.status_code, 201)
AssertionError: 200 != 201

======================================================================
FAIL: test_create_two_equals_users (test_api.TestAccountView)
----------------------------------------------------------------------
Traceback (most recent call last):
  File "/home/nathan/Área de Trabalho/python/Q4/Kanvas/test_api.py", line 134, in test_create_two_equals_users
    self.assertEqual(response.status_code, 201)
AssertionError: 200 != 201

======================================================================
FAIL: test_student_can_submit_an_activity (test_api.TestActivityView)
----------------------------------------------------------------------
Traceback (most recent call last):
  File "/home/nathan/Área de Trabalho/python/Q4/Kanvas/test_api.py", line 885, in test_student_can_submit_an_activity
    self.assertEqual(submission.status_code, 201)
AssertionError: 400 != 201

======================================================================
FAIL: test_student_can_view_only_your_submissions (test_api.TestActivityView)
----------------------------------------------------------------------
Traceback (most recent call last):
  File "/home/nathan/Área de Trabalho/python/Q4/Kanvas/test_api.py", line 1088, in test_student_can_view_only_your_submissions
    self.assertListEqual(submissions.json(), [{"id": 1, "grade": None, "repo": "http://gitlab.com/submission1", "user_id": 2, "activity_id": 1},
AssertionError: Lists differ: [{'id': 2, 'grade': None, 'repo': 'http://gitlab.[45 chars]: 2}] != [{'id': 1, 'grade': None, 'repo': 'http://gitlab.[144 chars]: 2}]

First differing element 0:
{'id': 2, 'grade': None, 'repo': 'http://gitlab.[44 chars]': 2}
{'id': 1, 'grade': None, 'repo': 'http://gitlab.[44 chars]': 1}

Second list contains 1 additional elements.
First extra element 1:
{'id': 2, 'grade': None, 'repo': 'http://gitlab.com/submission2', 'user_id': 2, 'activity_id': 2}

- [{'activity_id': 2,
?                  ^

+ [{'activity_id': 1,
?                  ^

+   'grade': None,
+   'id': 1,
+   'repo': 'http://gitlab.com/submission1',
+   'user_id': 2},
+  {'activity_id': 2,
    'grade': None,
    'id': 2,
    'repo': 'http://gitlab.com/submission2',
    'user_id': 2}]

======================================================================
FAIL: test_anonymous_can_filter_courses (test_api.TestCourseView)
----------------------------------------------------------------------
Traceback (most recent call last):
  File "/home/nathan/Área de Trabalho/python/Q4/Kanvas/test_api.py", line 329, in test_anonymous_can_filter_courses
    self.assertEqual(
AssertionError: [{'id': 1, 'name': 'course1', 'users': []}] != {'id': 1, 'name': 'course1', 'users': []}

======================================================================
FAIL: test_enroll_students_with_invalid_id (test_api.TestCourseView)
----------------------------------------------------------------------
Traceback (most recent call last):
  File "/home/nathan/Área de Trabalho/python/Q4/Kanvas/test_api.py", line 561, in test_enroll_students_with_invalid_id
    self.assertDictEqual(response.json(), {"errors": "invalid user_id list"})
AssertionError: {'errors': 'Only students can be enrolled in the course.'} != {'errors': 'invalid user_id list'}
- {'errors': 'Only students can be enrolled in the course.'}
+ {'errors': 'invalid user_id list'}

----------------------------------------------------------------------
Ran 30 tests in 17.125s

FAILED (failures=8, errors=1)
Destroying test database for alias 'default' ('file:memorydb_default?mode=memory&cache=shared')...
